Workbook
Name Slicer_age_grouped: #N/A
Name Slicer_education: #N/A
Name Slicer_gender: #N/A
Name Slicer_loan_status: #N/A

Sheet Loan Payment Data
A1: Loan_ID | B1: loan_status | C1: Principal | D1: terms | E1: effective_date | F1: due_date | G1: paid_off_time | H1: past_due_days | I1: delinquency_category | J1: Delinquency_Category_Funct | K1: age | L1: age_grouped | M1: Age_Grouped_Funct | N1: education | O1: Education_Funct | P1: gender | Q1: Gender_Funct
A2: xqd20166231 | B2: PAIDOFF | C2: 1000 | D2: 30 | E2: 42591 | F2: 42561 | G2: 9/14/2016 19:31 | I2: Current | J2: =IF(H2 = " ", "Current", IF(H2 = 0, "Current", IF(H2 <= 39, "1 - 39 Days", IF(H2 <= 80, "40 - 80 Days")))) -> Current | K2: 45 | L2: Mature | M2: =IF(K2 <= 25, " Young Adults", IF(K2 <= 33, "Middle Aged", IF(K2 <= 49, "Mature", IF(K2 <= 100, "Old")))) -> Mature | N2: high school or below | O2: =PROPER(N2) -> High School Or Below | P2: male | Q2: =PROPER(P2) -> Male
A3: xqd20168902 | B3: PAIDOFF | C3: 1000 | D3: 30 | E3: 42591 | F3: 42561 | G3: 42561.375 | I3: Current | J3: =IF(H3 = " ", "Current", IF(H3 = 0, "Current", IF(H3 <= 39, "1 - 39 Days", IF(H3 <= 80, "40 - 80 Days")))) -> Current | K3: 50 | L3: Old | M3: =IF(K3 <= 25, " Young Adults", IF(K3 <= 33, "Middle Aged", IF(K3 <= 49, "Mature", IF(K3 <= 100, "Old")))) -> Old | N3: bachelor | O3: =PROPER(N3) -> Bachelor | P3: female | Q3: =PROPER(P3) -> Female
A4: xqd20160003 | B4: PAIDOFF | C4: 1000 | D4: 30 | E4: 42591 | F4: 42561 | G4: 9/25/2016 16:58 | I4: Current | J4: =IF(H4 = " ", "Current", IF(H4 = 0, "Current", IF(H4 <= 39, "1 - 39 Days", IF(H4 <= 80, "40 - 80 Days")))) -> Current | K4: 33 | L4: Middle Aged | M4: =IF(K4 <= 25, " Young Adults", IF(K4 <= 33, "Middle Aged", IF(K4 <= 49, "Mature", IF(K4 <= 100, "Old")))) -> Middle Aged | N4: bachelor | O4: =PROPER(N4) -> Bachelor | P4: female | Q4: =PROPER(P4) -> Female
A5: xqd20160004 | B5: PAIDOFF | C5: 1000 | D5: 15 | E5: 42591 | F5: 9/22/2016 | G5: 9/22/2016 20:00 | I5: Current | J5: =IF(H5 = " ", "Current", IF(H5 = 0, "Current", IF(H5 <= 39, "1 - 39 Days", IF(H5 <= 80, "40 - 80 Days")))) -> Current | K5: 27 | L5: Middle Aged | M5: =IF(K5 <= 25, " Young Adults", IF(K5 <= 33, "Middle Aged", IF(K5 <= 49, "Mature", IF(K5 <= 100, "Old")))) -> Middle Aged | N5: college | O5: =PROPER(N5) -> College | P5: male | Q5: =PROPER(P5) -> Male
A6: xqd20160005 | B6: PAIDOFF | C6: 1000 | D6: 30 | E6: 42622 | F6: 42592 | G6: 9/23/2016 21:36 | I6: Current | J6: =IF(H6 = " ", "Current", IF(H6 = 0, "Current", IF(H6 <= 39, "1 - 39 Days", IF(H6 <= 80, "40 - 80 Days")))) -> Current | K6: 28 | L6: Middle Aged | M6: =IF(K6 <= 25, " Young Adults", IF(K6 <= 33, "Middle Aged", IF(K6 <= 49, "Mature", IF(K6 <= 100, "Old")))) -> Middle Aged | N6: college | O6: =PROPER(N6) -> College | P6: female | Q6: =PROPER(P6) -> Female
A7: xqd20160706 | B7: PAIDOFF | C7: 300 | D7: 7 | E7: 42622 | F7: 9/15/2016 | G7: 42622.573 | I7: Current | J7: =IF(H7 = " ", "Current", IF(H7 = 0, "Current", IF(H7 <= 39, "1 - 39 Days", IF(H7 <= 80, "40 - 80 Days")))) -> Current | K7: 35 | L7: Mature | M7: =IF(K7 <= 25, " Young Adults", IF(K7 <= 33, "Middle Aged", IF(K7 <= 49, "Mature", IF(K7 <= 100, "Old")))) -> Mature | N7: master or above | O7: =PROPER(N7) -> Master Or Above | P7: male | Q7: =PROPER(P7) -> Male
A8: xqd20160007 | B8: PAIDOFF | C8: 1000 | D8: 30 | E8: 42622 | F8: 42592 | G8: 42561.963 | I8: Current | J8: =IF(H8 = " ", "Current", IF(H8 = 0, "Current", IF(H8 <= 39, "1 - 39 Days", IF(H8 <= 80, "40 - 80 Days")))) -> Current | K8: 29 | L8: Middle Aged | M8: =IF(K8 <= 25, " Young Adults", IF(K8 <= 33, "Middle Aged", IF(K8 <= 49, "Mature", IF(K8 <= 100, "Old")))) -> Middle Aged | N8: college | O8: =PROPER(N8) -> College | P8: male | Q8: =PROPER(P8) -> Male
A9: xqd20160008 | B9: PAIDOFF | C9: 1000 | D9: 30 | E9: 42622 | F9: 42592 | G9: 42500.856 | I9: Current | J9: =IF(H9 = " ", "Current", IF(H9 = 0, "Current", IF(H9 <= 39, "1 - 39 Days", IF(H9 <= 80, "40 - 80 Days")))) -> Current | K9: 36 | L9: Mature | M9: =IF(K9 <= 25, " Young Adults", IF(K9 <= 33, "Middle Aged", IF(K9 <= 49, "Mature", IF(K9 <= 100, "Old")))) -> Mature | N9: college | O9: =PROPER(N9) -> College | P9: male | Q9: =PROPER(P9) -> Male
A10: xqd20160909 | B10: PAIDOFF | C10: 1000 | D10: 30 | E10: 42622 | F10: 42592 | G10: 42592.667 | I10: Current | J10: =IF(H10 = " ", "Current", IF(H10 = 0, "Current", IF(H10 <= 39, "1 - 39 Days", IF(H10 <= 80, "40 - 80 Days")))) -> Current | K10: 28 | L10: Middle Aged | M10: =IF(K10 <= 25, " Young Adults", IF(K10 <= 33, "Middle Aged", IF(K10 <= 49, "Mature", IF(K10 <= 100, "Old")))) -> Middle Aged | N10: college | O10: =PROPER(N10) -> College | P10: male | Q10: =PROPER(P10) -> Male
A11: xqd20160010 | B11: PAIDOFF | C11: 800 | D11: 15 | E11: 42652 | F11: 9/24/2016 | G11: 9/24/2016 13:00 | I11: Current | J11: =IF(H11 = " ", "Current", IF(H11 = 0, "Current", IF(H11 <= 39, "1 - 39 Days", IF(H11 <= 80, "40 - 80 Days")))) -> Current | K11: 26 | L11: Middle Aged | M11: =IF(K11 <= 25, " Young Adults", IF(K11 <= 33, "Middle Aged", IF(K11 <= 49, "Mature", IF(K11 <= 100, "Old")))) -> Middle Aged | N11: college | O11: =PROPER(N11) -> College | P11: male | Q11: =PROPER(P11) -> Male
A12: xqd20160011 | B12: PAIDOFF | C12: 300 | D12: 7 | E12: 42652 | F12: 9/16/2016 | G12: 42683.799 | I12: Current | J12: =IF(H12 = " ", "Current", IF(H12 = 0, "Current", IF(H12 <= 39, "1 - 39 Days", IF(H12 <= 80, "40 - 80 Days")))) -> Current | K12: 29 | L12: Middle Aged | M12: =IF(K12 <= 25, " Young Adults", IF(K12 <= 33, "Middle Aged", IF(K12 <= 49, "Mature", IF(K12 <= 100, "Old")))) -> Middle Aged | N12: college | O12: =PROPER(N12) -> College | P12: male | Q12: =PROPER(P12) -> Male
A13: xqd20160012 | B13: PAIDOFF | C13: 1000 | D13: 15 | E13: 42652 | F13: 42623 | G13: 42623.667 | I13: Current | J13: =IF(H13 = " ", "Current", IF(H13 = 0, "Current", IF(H13 <= 39, "1 - 39 Days", IF(H13 <= 80, "40 - 80 Days")))) -> Current | K13: 39 | L13: Mature | M13: =IF(K13 <= 25, " Young Adults", IF(K13 <= 33, "Middle Aged", IF(K13 <= 49, "Mature", IF(K13 <= 100, "Old")))) -> Mature | N13: high school or below | O13: =PROPER(N13) -> High School Or Below | P13: male | Q13: =PROPER(P13) -> Male
A14: xqd20160013 | B14: PAIDOFF | C14: 1000 | D14: 30 | E14: 42652 | F14: 42623 | G14: 42561.981 | I14: Current | J14: =IF(H14 = " ", "Current", IF(H14 = 0, "Current", IF(H14 <= 39, "1 - 39 Days", IF(H14 <= 80, "40 - 80 Days")))) -> Current | K14: 26 | L14: Middle Aged | M14: =IF(K14 <= 25, " Young Adults", IF(K14 <= 33, "Middle Aged", IF(K14 <= 49, "Mature", IF(K14 <= 100, "Old")))) -> Middle Aged | N14: college | O14: =PROPER(N14) -> College | P14: male | Q14: =PROPER(P14) -> Male
A15: xqd20160014 | B15: PAIDOFF | C15: 900 | D15: 7 | E15: 42652 | F15: 9/16/2016 | G15: 9/13/2016 21:57 | I15: Current | J15: =IF(H15 = " ", "Current", IF(H15 = 0, "Current", IF(H15 <= 39, "1 - 39 Days", IF(H15 <= 80, "40 - 80 Days")))) -> Current | K15: 26 | L15: Middle Aged | M15: =IF(K15 <= 25, " Young Adults", IF(K15 <= 33, "Middle Aged", IF(K15 <= 49, "Mature", IF(K15 <= 100, "Old")))) -> Middle Aged | N15: college | O15: =PROPER(N15) -> College | P15: female | Q15: =PROPER(P15) -> Female
A16: xqd20160015 | B16: PAIDOFF | C16: 1000 | D16: 7 | E16: 42652 | F16: 9/16/2016 | G16: 9/15/2016 14:27 | I16: Current | J16: =IF(H16 = " ", "Current", IF(H16 = 0, "Current", IF(H16 <= 39, "1 - 39 Days", IF(H16 <= 80, "40 - 80 Days")))) -> Current | K16: 27 | L16: Middle Aged | M16: =IF(K16 <= 25, " Young Adults", IF(K16 <= 33, "Middle Aged", IF(K16 <= 49, "Mature", IF(K16 <= 100, "Old")))) -> Middle Aged | N16: high school or below | O16: =PROPER(N16) -> High School Or Below | P16: male | Q16: =PROPER(P16) -> Male
A17: xqd20160016 | B17: PAIDOFF | C17: 800 | D17: 15 | E17: 42652 | F17: 9/24/2016 | G17: 9/24/2016 16:00 | I17: Current | J17: =IF(H17 = " ", "Current", IF(H17 = 0, "Current", IF(H17 <= 39, "1 - 39 Days", IF(H17 <= 80, "40 - 80 Days")))) -> Current | K17: 26 | L17: Middle Aged | M17: =IF(K17 <= 25, " Young Adults", IF(K17 <= 33, "Middle Aged", IF(K17 <= 49, "Mature", IF(K17 <= 100, "Old")))) -> Middle Aged | N17: college | O17: =PROPER(N17) -> College | P17: male | Q17: =PROPER(P17) -> Male
A18: xqd20160017 | B18: PAIDOFF | C18: 1000 | D18: 30 | E18: 42652 | F18: 42623 | G18: 9/27/2016 14:21 | I18: Current | J18: =IF(H18 = " ", "Current", IF(H18 = 0, "Current", IF(H18 <= 39, "1 - 39 Days", IF(H18 <= 80, "40 - 80 Days")))) -> Current | K18: 40 | L18: Mature | M18: =IF(K18 <= 25, " Young Adults", IF(K18 <= 33, "Middle Aged", IF(K18 <= 49, "Mature", IF(K18 <= 100, "Old")))) -> Mature | N18: high school or below | O18: =PROPER(N18) -> High School Or Below | P18: male | Q18: =PROPER(P18) -> Male
A19: xqd20160018 | B19: PAIDOFF | C19: 1000 | D19: 15 | E19: 42652 | F19: 9/24/2016 | G19: 9/23/2016 18:49 | I19: Current | J19: =IF(H19 = " ", "Current", IF(H19 = 0, "Current", IF(H19 <= 39, "1 - 39 Days", IF(H19 <= 80, "40 - 80 Days")))) -> Current | K19: 32 | L19: Middle Aged | M19: =IF(K19 <= 25, " Young Adults", IF(K19 <= 33, "Middle Aged", IF(K19 <= 49, "Mature", IF(K19 <= 100, "Old")))) -> Middle Aged | N19: high school or below | O19: =PROPER(N19) -> High School Or Below | P19: male | Q19: =PROPER(P19) -> Male
A20: xqd20160019 | B20: PAIDOFF | C20: 1000 | D20: 30 | E20: 42652 | F20: 42623 | G20: 42500.92 | I20: Current | J20: =IF(H20 = " ", "Current", IF(H20 = 0, "Current", IF(H20 <= 39, "1 - 39 Days", IF(H20 <= 80, "40 - 80 Days")))) -> Current | K20: 32 | L20: Middle Aged | M20: =IF(K20 <= 25, " Young Adults", IF(K20 <= 33, "Middle Aged", IF(K20 <= 49, "Mature", IF(K20 <= 100, "Old")))) -> Middle Aged | N20: high school or below | O20: =PROPER(N20) -> High School Or Below | P20: male | Q20: =PROPER(P20) -> Male
A21: xqd20160020 | B21: PAIDOFF | C21: 800 | D21: 30 | E21: 42652 | F21: 42623 | G21: 9/23/2016 7:42 | I21: Current | J21: =IF(H21 = " ", "Current", IF(H21 = 0, "Current", IF(H21 <= 39, "1 - 39 Days", IF(H21 <= 80, "40 - 80 Days")))) -> Current | K21: 26 | L21: Middle Aged | M21: =IF(K21 <= 25, " Young Adults", IF(K21 <= 33, "Middle Aged", IF(K21 <= 49, "Mature", IF(K21 <= 100, "Old")))) -> Middle Aged | N21: college | O21: =PROPER(N21) -> College | P21: male | Q21: =PROPER(P21) -> Male
A22: xqd20160021 | B22: PAIDOFF | C22: 1000 | D22: 30 | E22: 42652 | F22: 42623 | G22: 42623.375 | I22: Current | J22: =IF(H22 = " ", "Current", IF(H22 = 0, "Current", IF(H22 <= 39, "1 - 39 Days", IF(H22 <= 80, "40 - 80 Days")))) -> Current | K22: 26 | L22: Middle Aged | M22: =IF(K22 <= 25, " Young Adults", IF(K22 <= 33, "Middle Aged", IF(K22 <= 49, "Mature", IF(K22 <= 100, "Old")))) -> Middle Aged | N22: college | O22: =PROPER(N22) -> College | P22: male | Q22: =PROPER(P22) -> Male
A23: xqd20160022 | B23: PAIDOFF | C23: 1000 | D23: 30 | E23: 42652 | F23: 42623 | G23: 42592.715 | I23: Current | J23: =IF(H23 = " ", "Current", IF(H23 = 0, "Current", IF(H23 <= 39, "1 - 39 Days", IF(H23 <= 80, "40 - 80 Days")))) -> Current | K23: 43 | L23: Mature | M23: =IF(K23 <= 25, " Young Adults", IF(K23 <= 33, "Middle Aged", IF(K23 <= 49, "Mature", IF(K23 <= 100, "Old")))) -> Mature | N23: high school or below | O23: =PROPER(N23) -> High School Or Below | P23: female | Q23: =PROPER(P23) -> Female
A24: xqd20160023 | B24: PAIDOFF | C24: 1000 | D24: 30 | E24: 42652 | F24: 42623 | G24: 42623.958 | I24: Current | J24: =IF(H24 = " ", "Current", IF(H24 = 0, "Current", IF(H24 <= 39, "1 - 39 Days", IF(H24 <= 80, "40 - 80 Days")))) -> Current | K24: 25 | L24: Young Adults | M24: =IF(K24 <= 25, " Young Adults", IF(K24 <= 33, "Middle Aged", IF(K24 <= 49, "Mature", IF(K24 <= 100, "Old")))) -> Young Adults | N24: high school or below | O24: =PROPER(N24) -> High School Or Below | P24: male | Q24: =PROPER(P24) -> Male
A25: xqd20160024 | B25: PAIDOFF | C25: 1000 | D25: 15 | E25: 42652 | F25: 9/24/2016 | G25: 9/24/2016 13:00 | I25: Current | J25: =IF(H25 = " ", "Current", IF(H25 = 0, "Current", IF(H25 <= 39, "1 - 39 Days", IF(H25 <= 80, "40 - 80 Days")))) -> Current | K25: 26 | L25: Middle Aged | M25: =IF(K25 <= 25, " Young Adults", IF(K25 <= 33, "Middle Aged", IF(K25 <= 49, "Mature", IF(K25 <= 100, "Old")))) -> Middle Aged | N25: college | O25: =PROPER(N25) -> College | P25: male | Q25: =PROPER(P25) -> Male
A26: xqd20160025 | B26: PAIDOFF | C26: 1000 | D26: 30 | E26: 42652 | F26: 42623 | G26: 42439.535 | I26: Current | J26: =IF(H26 = " ", "Current", IF(H26 = 0, "Current", IF(H26 <= 39, "1 - 39 Days", IF(H26 <= 80, "40 - 80 Days")))) -> Current | K26: 26 | L26: Middle Aged | M26: =IF(K26 <= 25, " Young Adults", IF(K26 <= 33, "Middle Aged", IF(K26 <= 49, "Mature", IF(K26 <= 100, "Old")))) -> Middle Aged | N26: college | O26: =PROPER(N26) -> College | P26: male | Q26: =PROPER(P26) -> Male
A27: xqd20160026 | B27: PAIDOFF | C27: 1000 | D27: 30 | E27: 42652 | F27: 42623 | G27: 9/29/2016 12:18 | I27: Current | J27: =IF(H27 = " ", "Current", IF(H27 = 0, "Current", IF(H27 <= 39, "1 - 39 Days", IF(H27 <= 80, "40 - 80 Days")))) -> Current | K27: 29 | L27: Middle Aged | M27: =IF(K27 <= 25, " Young Adults", IF(K27 <= 33, "Middle Aged", IF(K27 <= 49, "Mature", IF(K27 <= 100, "Old")))) -> Middle Aged | N27: high school or below | O27: =PROPER(N27) -> High School Or Below | P27: male | Q27: =PROPER(P27) -> Male
A28: xqd20160027 | B28: PAIDOFF | C28: 800 | D28: 15 | E28: 42652 | F28: 9/24/2016 | G28: 9/21/2016 20:16 | I28: Current | J28: =IF(H28 = " ", "Current", IF(H28 = 0, "Current", IF(H28 <= 39, "1 - 39 Days", IF(H28 <= 80, "40 - 80 Days")))) -> Current | K28: 39 | L28: Mature | M28: =IF(K28 <= 25, " Young Adults", IF(K28 <= 33, "Middle Aged", IF(K28 <= 49, "Mature", IF(K28 <= 100, "Old")))) -> Mature | N28: bachelor | O28: =PROPER(N28) -> Bachelor | P28: male | Q28: =PROPER(P28) -> Male
A29: xqd20170088 | B29: PAIDOFF | C29: 1000 | D29: 15 | E29: 42652 | F29: 9/24/2016 | G29: 9/23/2016 8:21 | I29: Current | J29: =IF(H29 = " ", "Current", IF(H29 = 0, "Current", IF(H29 <= 39, "1 - 39 Days", IF(H29 <= 80, "40 - 80 Days")))) -> Current | K29: 34 | L29: Mature | M29: =IF(K29 <= 25, " Young Adults", IF(K29 <= 33, "Middle Aged", IF(K29 <= 49, "Mature", IF(K29 <= 100, "Old")))) -> Mature | N29: bachelor | O29: =PROPER(N29) -> Bachelor | P29: male | Q29: =PROPER(P29) -> Male
A30: xqd20160029 | B30: PAIDOFF | C30: 1000 | D30: 30 | E30: 42683 | F30: 42653 | G30: 9/22/2016 19:17 | I30: Current | J30: =IF(H30 = " ", "Current", IF(H30 = 0, "Current", IF(H30 <= 39, "1 - 39 Days", IF(H30 <= 80, "40 - 80 Days")))) -> Current | K30: 31 | L30: Middle Aged | M30: =IF(K30 <= 25, " Young Adults", IF(K30 <= 33, "Middle Aged", IF(K30 <= 49, "Mature", IF(K30 <= 100, "Old")))) -> Middle Aged | N30: college | O30: =PROPER(N30) -> College | P30: male | Q30: =PROPER(P30) -> Male
A31: xqd20160030 | B31: PAIDOFF | C31: 1000 | D31: 30 | E31: 42683 | F31: 42653 | G31: 42623.731 | I31: Current | J31: =IF(H31 = " ", "Current", IF(H31 = 0, "Current", IF(H31 <= 39, "1 - 39 Days", IF(H31 <= 80, "40 - 80 Days")))) -> Current | K31: 33 | L31: Middle Aged | M31: =IF(K31 <= 25, " Young Adults", IF(K31 <= 33, "Middle Aged", IF(K31 <= 49, "Mature", IF(K31 <= 100, "Old")))) -> Middle Aged | N31: college | O31: =PROPER(N31) -> College | P31: male | Q31: =PROPER(P31) -> Male
A32: xqd88160031 | B32: PAIDOFF | C32: 800 | D32: 15 | E32: 42683 | F32: 9/25/2016 | G32: 9/24/2016 14:41 | I32: Current | J32: =IF(H32 = " ", "Current", IF(H32 = 0, "Current", IF(H32 <= 39, "1 - 39 Days", IF(H32 <= 80, "40 - 80 Days")))) -> Current | K32: 33 | L32: Middle Aged | M32: =IF(K32 <= 25, " Young Adults", IF(K32 <= 33, "Middle Aged", IF(K32 <= 49, "Mature", IF(K32 <= 100, "Old")))) -> Middle Aged | N32: high school or below | O32: =PROPER(N32) -> High School Or Below | P32: male | Q32: =PROPER(P32) -> Male
A33: xqd20160032 | B33: PAIDOFF | C33: 1000 | D33: 30 | E33: 42683 | F33: 42653 | G33: 42561.908 | I33: Current | J33: =IF(H33 = " ", "Current", IF(H33 = 0, "Current", IF(H33 <= 39, "1 - 39 Days", IF(H33 <= 80, "40 - 80 Days")))) -> Current | K33: 37 | L33: Mature | M33: =IF(K33 <= 25, " Young Adults", IF(K33 <= 33, "Middle Aged", IF(K33 <= 49, "Mature", IF(K33 <= 100, "Old")))) -> Mature | N33: college | O33: =PROPER(N33) -> College | P33: male | Q33: =PROPER(P33) -> Male
A34: xqd20160033 | B34: PAIDOFF | C34: 1000 | D34: 30 | E34: 42683 | F34: 42653 | G34: 42623.739 | I34: Current | J34: =IF(H34 = " ", "Current", IF(H34 = 0, "Current", IF(H34 <= 39, "1 - 39 Days", IF(H34 <= 80, "40 - 80 Days")))) -> Current | K34: 27 | L34: Middle Aged | M34: =IF(K34 <= 25, " Young Adults", IF(K34 <= 33, "Middle Aged", IF(K34 <= 49, "Mature", IF(K34 <= 100, "Old")))) -> Middle Aged | N34: college | O34: =PROPER(N34) -> College | P34: male | Q34: =PROPER(P34) -> Male
A35: xqd22169034 | B35: PAIDOFF | C35: 1000 | D35: 30 | E35: 42683 | F35: 42653 | G35: 42623.308 | I35: Current | J35: =IF(H35 = " ", "Current", IF(H35 = 0, "Current", IF(H35 <= 39, "1 - 39 Days", IF(H35 <= 80, "40 - 80 Days")))) -> Current | K35: 37 | L35: Mature | M35: =IF(K35 <= 25, " Young Adults", IF(K35 <= 33, "Middle Aged", IF(K35 <= 49, "Mature", IF(K35 <= 100, "Old")))) -> Mature | N35: college | O35: =PROPER(N35) -> College | P35: male | Q35: =PROPER(P35) -> Male
A36: xqd20160035 | B36: PAIDOFF | C36: 800 | D36: 15 | E36: 42683 | F36: 9/25/2016 | G36: 9/25/2016 21:49 | I36: Current | J36: =IF(H36 = " ", "Current", IF(H36 = 0, "Current", IF(H36 <= 39, "1 - 39 Days", IF(H36 <= 80, "40 - 80 Days")))) -> Current | K36: 33 | L36: Middle Aged | M36: =IF(K36 <= 25, " Young Adults", IF(K36 <= 33, "Middle Aged", IF(K36 <= 49, "Mature", IF(K36 <= 100, "Old")))) -> Middle Aged | N36: college | O36: =PROPER(N36) -> College | P36: male | Q36: =PROPER(P36) -> Male
A37: xqd20160036 | B37: PAIDOFF | C37: 800 | D37: 15 | E37: 42683 | F37: 9/25/2016 | G37: 9/25/2016 9:00 | I37: Current | J37: =IF(H37 = " ", "Current", IF(H37 = 0, "Current", IF(H37 <= 39, "1 - 39 Days", IF(H37 <= 80, "40 - 80 Days")))) -> Current | K37: 29 | L37: Middle Aged | M37: =IF(K37 <= 25, " Young Adults", IF(K37 <= 33, "Middle Aged", IF(K37 <= 49, "Mature", IF(K37 <= 100, "Old")))) -> Middle Aged | N37: bachelor | O37: =PROPER(N37) -> Bachelor | P37: male | Q37: =PROPER(P37) -> Male
A38: xqd20160037 | B38: PAIDOFF | C38: 1000 | D38: 30 | E38: 42683 | F38: 42653 | G38: 42653.667 | I38: Current | J38: =IF(H38 = " ", "Current", IF(H38 = 0, "Current", IF(H38 <= 39, "1 - 39 Days", IF(H38 <= 80, "40 - 80 Days")))) -> Current | K38: 27 | L38: Middle Aged | M38: =IF(K38 <= 25, " Young Adults", IF(K38 <= 33, "Middle Aged", IF(K38 <= 49, "Mature", IF(K38 <= 100, "Old")))) -> Middle Aged | N38: high school or below | O38: =PROPER(N38) -> High School Or Below | P38: male | Q38: =PROPER(P38) -> Male
A39: xqd20160038 | B39: PAIDOFF | C39: 700 | D39: 15 | E39: 42683 | F39: 9/25/2016 | G39: 9/25/2016 13:00 | I39: Current | J39: =IF(H39 = " ", "Current", IF(H39 = 0, "Current", IF(H39 <= 39, "1 - 39 Days", IF(H39 <= 80, "40 - 80 Days")))) -> Current | K39: 33 | L39: Middle Aged | M39: =IF(K39 <= 25, " Young Adults", IF(K39 <= 33, "Middle Aged", IF(K39 <= 49, "Mature", IF(K39 <= 100, "Old")))) -> Middle Aged | N39: high school or below | O39: =PROPER(N39) -> High School Or Below | P39: male | Q39: =PROPER(P39) -> Male
A40: xqd20160039 | B40: PAIDOFF | C40: 1000 | D40: 15 | E40: 42683 | F40: 9/25/2016 | G40: 9/25/2016 9:00 | I40: Current | J40: =IF(H40 = " ", "Current", IF(H40 = 0, "Current", IF(H40 <= 39, "1 - 39 Days", IF(H40 <= 80, "40 - 80 Days")))) -> Current | K40: 24 | L40: Young Adults | M40: =IF(K40 <= 25, " Young Adults", IF(K40 <= 33, "Middle Aged", IF(K40 <= 49, "Mature", IF(K40 <= 100, "Old")))) -> Young Adults | N40: college | O40: =PROPER(N40) -> College | P40: male | Q40: =PROPER(P40) -> Male
...

Sheet KPI Summary
A1: KPI SUMMARY
A3: KPIs | B3: Values | C3: Answers
A4: Total Loans | B4: =COUNTA('Loan Payment Data'!A2:A501) -> 500 | C4: How many loans are in the dataset?
A5: Total Principal | B5: =SUM('Loan Payment Data'!C2:C502) -> 471600 | C5: What is the total principal value of the portfolio?
A6: Loans in Collection | B6: =COUNTIF('Loan Payment Data'!B2:B501, "COLLECTION") -> 100 | C6: How many loans are currently classified as COLLECTION?
A7: Principal In Collection | B7: =SUMIFS('Loan Payment Data'!C2:C501, 'Loan Payment Data'!B2:B501, "COLLECTION") -> 95400 | C7: How much principal is associated with laons currently in COLLECTION?
A8: 40+ Days Loans | B8: =COUNTIF('Loan Payment Data'!I2:I501, " 40 - 80 Days") -> 99 | C8: How many Loans fall into the most severe delinqeuncy band we've defined?
A9: Collection Rate | B9: =COUNTIFS('Loan Payment Data'!B2:B501,"COLLECTION")/COUNTA('Loan Payment Data'!A2:A501) -> 0.2 | C9: What percentage of all loans are currently classified as COLLECTION?

Sheet  Pivot Tables
A1: Pivot Tables
A8: Row Labels | B8: Count of Loan_ID | C8: Sum of Principal
A9: 9/13/2016 | B9: 23 | C9: 20900
A10: 9/14/2016 | B10: 33 | C10: 31400
A11: 42591 | B11: 4 | C11: 4000
A12: 42622 | B12: 15 | C12: 13700
A13: 42652 | B13: 46 | C13: 43200
A14: 42683 | B14: 231 | C14: 219000
A15: 42713 | B15: 148 | C15: 139400
A16: Grand Total | B16: 500 | C16: 471600
A28: Count of Loan_ID | B28: Column Labels
A29: Row Labels | B29: COLLECTION | C29: COLLECTION_PAIDOFF | D29: PAIDOFF | E29: Grand Total
A30: female | B30: 10 | C30: 14 | D30: 53 | E30: 77
A31: male | B31: 90 | C31: 86 | D31: 247 | E31: 423
A32: Grand Total | B32: 100 | C32: 100 | D32: 300 | E32: 500
A42: Row Labels | B42: Sum of Principal | C42: Count of Loan_ID
A43: Young Adults | B43: 70700 | C43: 75
A44: Mature | B44: 141600 | C44: 153
A45: Middle Aged | B45: 254700 | C45: 267
A46: Old | B46: 4600 | C46: 5
A47: Grand Total | B47: 471600 | C47: 500
A62: Row Labels | B62: Count of Loan_ID | C62: Sum of Principal
A63: COLLECTION | B63: 100 | C63: 95400
A64: COLLECTION_PAIDOFF | B64: 100 | C64: 95700
A65: PAIDOFF | B65: 300 | C65: 280500
A66: Grand Total | B66: 500 | C66: 471600

Sheet Dashaboard
A1: LOAN PAYMENT DASHBOARD
